Workbook

Sheet Tuntihinnoittelut
A1: Tuntihinnoittelut
B3: Tuntihinta | C3: 42
A5: POS-1 | B5: Kuvaus | C5: Tunnit
A6: 1 | B6: Työmaan perustus + työmaataulu ja ilmoitukset | C6: 8
A7: 2 | B7: Suojaukset | C7: 16
A8: 3
A9: 4 | B9: Roudaukset | C9: 60
A10: 5 | B10: Keittiön asennus | C10: 60
A11: 6 | B11: Wc-kalusteiden asennus | C11: 16
A12: 7 | B12: wc-varusteiden asennus | C12: 16
A13: 8
A14: 9 | B14: Lasien asennukset | C14: 60
A15: 10
A16: 11 | B16: Palopalkkien koteloinnit | C16: 60
A17: 12
A18: 13
A19: 14
A20: 15
A21: 16
A22: 17
A23: 18
A24: 19
A25: 20
A26: 21
A27: 22
A28: 23
... A35: 30
B37: Yhteensä | C37: =SUM(C6:C36) -> 296
B39: Hinta | C39: =C3*C37 -> 12432

Sheet Materiaalihinnoittelut
A1: Materiaalihinnoittelut
A3: POS-1 | B3: Kuvaus | C3: Hinta | D3: Kuvaus | E3: kpl | F3: Yht.
A4: 1 | B4: GN | C4: 4.8 | E4: 35 | F4: =C4*E4 -> 168
A5: 2 | B5: GEK | C5: 3.1 | F5: =C5*E5 -> 0
A6: 3 | B6: Saneerauskipsi 6MM | C6: 9.7 | F6: =C6*E6 -> 0
A7: 4 | B7: 66 ranka | C7: 1.5 | F7: =C7*E7 -> 0
A8: 5 | B8: 66 alakisko | C8: 1.4 | F8: =C8*E8 -> 0
A9: 6 | B9: 66 kertopuu | C9: 2.9 | F9: =C9*E9 -> 0
A10: 7 | B10: 95 ranka | C10: 1.7 | F10: =C10*E10 -> 0
A11: 8 | B11: 95 alakisko | C11: 1.6 | F11: =C11*E11 -> 0
A12: 9 | B12: 92 keropuu | C12: 2.6 | F12: =C12*E12 -> 0
A13: 10 | B13: Väliseinävilla | C13: 4.7 | F13: =C13*E13 -> 0
A14: 11 | B14: 120 ranka | C14: 2.3 | F14: =C14*E14 -> 0
A15: 12 | B15: 120 alakisko | F15: =C15*E15 -> 0
A16: 13 | B16: XR66 ranka | C16: 2.18 | F16: =C16*E16 -> 0
A17: 14 | B17: Acounomic 66 kisko | C17: 4.1 | F17: =C17*E17 -> 0
A18: 15 | B18: XR95 ranka | C18: 2.18 | F18: =C18*E18 -> 0
A19: 16 | B19: Acounomic 95 kisko | C19: 4.24 | F19: =C19*E19 -> 0
A20: 17 | B20: GFR 120/1,2mm | C20: 7.84 | F20: =C20*E20 -> 0
A21: 18 | B21: GFR 95/1,2mm | C21: 7.05 | F21: =C21*E21 -> 0
A22: 19 | B22: GFR 70/1,2mm | C22: 6.44 | F22: =C22*E22 -> 0
A23: 20 | B23: GFS 70 | C23: 6.54 | F23: =C23*E23 -> 0
A24: 21 | B24: GFS 95 | C24: 7.2 | F24: =C24*E24 -> 0
A25: 22 | B25: GFS 120 | C25: 10.2 | F25: =C25*E25 -> 0
A26: 23 | B26: Vihtan lasiseinät, 900 ja 600 | C26: 500 | F26: =C26*E26 -> 0
A27: 24 | B27: 12mm hvauvaner, 12x240 | C27: 9.2 | F27: =C27*E27 -> 0
A28: 25 | B28: IBS 1 taustapelti 1200x2400 | C28: 22.78 | F28: =C28*E28 -> 0
A29: 26 | B29: Lattiakipsilevy Knauf KL 15mm, 900x2400 | C29: 7.26 | D29: m2 | F29: =C29*E29 -> 0
A30: 27 | B30: Lattiakipsi Lapikas 15mm 1200x2400 | C30: 16.86 | F30: =C30*E30 -> 0
A31: 28 | B31: Palosuojalevy knauf KPS 1200x2700x15 | C31: 19.99 | F31: =C31*E31 -> 0
A32: 29 | B32: Palonsuojalevy Gyproc GFL15 1200x3000 | C32: 23.69 | F32: =C32*E32 -> 0
A33: 30 | B33: Kipsilevy märkätila | C33: 22.97 | F33: =C33*E33 -> 0
A34: 31 | B34: Vesivaneri 12mm | C34: 48.92 | F34: =C34*E34 -> 0
A35: 32 | B35: Väliseinäpontti kahi, rei'itetty 300x85x198 | C35: 1.08 | F35: =C35*E35 -> 0
A36: 33 | B36: Weber ohutsaumalaasti | C36: 17.35 | F36: =C36*E36 -> 0
A37: 34 | B37: 9mm havuvaneri 1200x2440 | C37: 28.5 | F37: =C37*E37 -> 0
A38: 35 | B38: 15mm havuvaneri 1200x2440 | C38: 42.02 | F38: =C38*E38 -> 0
A39: 36 | B39: 24mm havuvaneri 1,2x2,40 suojakäsit. | C39: 27.94 | F39: =C39*E39 -> 0
A40: 37 | B40: 15mm koivuvaneri, 1500x3000 | C40: 66.37 | F40: =C40*E40 -> 0
A41: 38 | B41: Lattialastulevy 22x1200x2400 | C41: 12.75 | F41: =C41*E41 -> 0
...

Sheet Purkutyöt
A1: Purkutyöt
E2: Lattian käsittely | F2: Neliöhinta | G2: Huom.
A3: POS-1 | B3: Neliöhinnoittelu | C3: Määrä | E3: Matonpoistokone, lino tai muovi | F3: 20.65 | G3: Huomioitu 140 € / viikkovuokralla, n. 0,5h / m2
B4: Neliöt | E4: Timanttikone 400 Scanmaskin | F4: 20.65 | G4: Huomioitu 140 € / viikkovuokralla, n. 0,5h / m2
B5: Neliöhinta | C5: 75 | E5: Teräkulu, 160 € / paketti netto | F5: 160
E6: Kevythiomakone, wirbeli | F6: 10.76 | G6: Huomioitu 70 € / viikkovuokralla, n. 0,25h / m2
B7: Hinta Yhteensä | C7: =C4*C5 -> 0 | E7: Laikkakulu, kupari / karbidi / kpl netto | F7: 60
A11: POS-2 | B11: Kuvaus | C11: Tunnit | E11: MENEKKILASKURI
A12: 1 | B12: Purkutyöt | C12: 40 | E12: Paino-arviot / m2 | F12: Kg | G12: Määrä | H12: Yhteensä
A13: 2 | E13: Kipsilevyseinä, 2xEK + villa | F13: 50 | H13: =F13*G13 -> 0
A14: 3 | E14: 1m2 levykerros painaa n. 11 kg | H14: =F14*G14 -> 0
A15: 4 | H15: =F15*G15 -> 0
A16: 5 | E16: Tiiliseinä | F16: 270 | H16: =F16*G16 -> 0
A17: 6 | H17: =F17*G17 -> 0
A18: 7 | E18: Laatta + laasti | F18: 13 | H18: =F18*G18 -> 0
A19: 8 | H19: =F19*G19 -> 0
A20: 9 | E20: Valubetoni, 1cm kerros | F20: 25 | H20: =F20*G20 -> 0
A21: 10 | H21: =F21*G21 -> 0
A22: 11 | E22: Alakatto | F22: 10 | H22: =F22*G22 -> 0
A23: 12 | H23: =F23*G23 -> 0
A24: 13 | E24: Muovimatto | F24: 5 | H24: =F24*G24 -> 0
A25: 14 | E25: Lasiseinä 55.1 | F25: 23 | H25: =F25*G25 -> 0
A26: 15 | E26: Muut arviot, syötä kilomäärä | F26: 2000 | H26: =F26*G26 -> 0
A27: 16 | G27: Yht. Tonnia | H27: =SUM(H13:H26)/1000 -> 0
A28: 17
A29: 18
A30: 19
A31: 20 | E31: Materiaalit
E32: Vaihtolava.com | F32: Hinta | G32: Määrä | H32: Yht.
B33: Yhteensä | C33: =SUM(C12:C32) -> 40 | E33: Nosturipurku / päivähinta | F33: 2500 | H33: =F33*G33 -> 0
B34: Tuntiveloitushinta | C34: 42 | E34: Kuten pasilanraitio purku | H34: =F34*G34 -> 0
H35: =F35*G35 -> 0
B36: Työt, hinta | C36: =C33*C34 -> 1680 | H36: =F36*G36 -> 0
E37: Toimitus työmaalle | F37: 70 | G37: 10 | H37: =F37*G37 -> 700
B38: Materiaalit, hinta | C38: =H51+H71 -> 4330 | E38: Tyhjennys ja pois haku / kerta | F38: 140 | G38: 10 | H38: =F38*G38 -> 1400
E39: Punnitusmaksu / kerta | F39: 25 | G39: 10 | H39: =F39*G39 -> 250
E41: Tonnihinnat
E42: Rakennusjäte, LK2 | F42: 198 | G42: 10 | H42: =F42*G42 -> 1980
E43: Rakennusjäte | F43: 148 | H43: =F43*G43 -> 0
E44: Painekyllästetty puujäte | F44: 299 | H44: =F44*G44 -> 0
...

Sheet Väliseinät sisällä
A1: VÄLISEINÄT JA OTSAT
C2: Ohje laskentaan
A3: POS-1 | B3: Kuvaus | C3: Kate-% voi laskea jos seinä erikoinen ja pystyy hinnoittelemaan suoraan
A4: VS-1 | B4: neukkarien seinät | C4: Esim. sik-sak -seinän lisäprosenttiosuus tai märkätilalevyn osuus jne. | Q4: VS-1 | Z4: Saumaus ja akryyli laskettu hintoihin
G5: SEINÄN RAKENNUS
A6: K-600 | B6: Neliöt | H6: määrä | M6: Hinta / m2 / jm / kpl | Q6: EK - 66 LPR | R6: EK - 90 LPR | S6: EK - 66 XR | T6: EK - 90 XR | U6: EK+VANERI- 66 LPR | V6: EK+VANERI- 90 LPR | W6: EK+VANERI- 66 XR | X6: EK+VANERI- 90 XR | Z6: Työn hinta sis 80% sos | AA6: Määrä | AB6: yht.
A7: 1-kertanen | G7: Levy, m2 | H7: =(((B7*2)+(B8*4)+(B11*2)+(B12*4))+((B21*C21)*2)+(B14)+(B23))*1.1 -> 1553.2 | L7: GEK | M7: 4.1 | P7: Levy | Q7: =H7*$M$7 -> 6368.12 | R7: =H7*$M$7 -> 6368.12 | S7: =H7*$M$7 -> 6368.12 | T7: =H7*$M$7 -> 6368.12 | U7: =H7*($M$7/2)+(H7*$M$25/2) -> 12114.96 | V7: =H7*($M$7/2)+(H7*$M$25/2) -> 12114.96 | W7: =H7*($M$7/2)+(H7*$M$25/2) -> 12114.96 | X7: =H7*($M$7/2)+(H7*$M$25/2) -> 12114.96 | Y7: 1-kertanen | Z7: 27.9 | AA7: =B7 -> 0 | AB7: =Z7*AA7 -> 0
A8: 2-kertanen | B8: 335 | G8: Ranka, m | H8: =(((B7+B8+(B11*2)+(B12*2))*1.667)+(B21*1.667*C21))*1.1 -> 680.3027 | I8: Otsa max 600 | L8: GN | M8: 3.1 | P8: Ranka | Q8: =H8*$M$10 -> 1020.4541 | R8: =H8*$M$13 -> 1224.5449 | S8: =H8*$M$19 -> 1292.5751 | T8: =H8*$M$21 -> 1428.6357 | U8: =H8*$M$10 -> 1020.4541 | V8: =H8*$M$13 -> 1224.5449 | W8: =H8*$M$19 -> 1292.5751 | X8: =H8*$M$21 -> 1428.6357 | Y8: 2-kertanen | Z8: 37.44 | AA8: =B8 -> 335 | AB8: =Z8*AA8 -> 12542.4
G9: Alakisko, seinä, m / otsat max 600, m | H9: =(((B7+B8+B11+B12)*0.667)+(B21*2))*1.1 -> 311.7895 | I9: =((B7+B8+B11+B12)*1.666667)*1.1 -> 614.16679 | L9: Saneerauskipsi 6MM | M9: 5 | P9: Alakisko | Q9: =H9*$M$11 -> 561.2211 | R9: =H9*$M$14 -> 654.75795 | S9: =H9*$M$20 -> 1371.8738 | T9: =H9*$M$22 -> 1434.2317 | U9: =H9*$M$11 -> 561.2211 | V9: =H9*$M$14 -> 654.75795 | W9: =H9*$M$20 -> 1371.8738 | X9: =H9*$M$22 -> 1434.2317
A10: K-300 | G10: Villa, m2 | H10: =(B7+B8+B11+B12)*1.1 -> 368.5 | L10: 66 ranka | M10: 1.5 | P10: Villa | Q10: =+H10*$M$16 -> 1252.9 | R10: =+H10*$M$16 -> 1252.9 | S10: =+H10*$M$16 -> 1252.9 | T10: =+H10*$M$16 -> 1252.9 | U10: =+H10*$M$16 -> 1252.9 | V10: =+H10*$M$16 -> 1252.9 | W10: =+H10*$M$16 -> 1252.9 | X10: =+H10*$M$16 -> 1252.9 | Y10: K-300
A11: 1-kertainen | G11: Ruuvit, kpl / 1000 kpl pkt | H11: =(((B7+(B8*2)+B11+(B12*2))*30)+(B21*C21*30*2)+(B23*30))*1.1 -> 24486 | I11: =H11/1000 -> 24.486 | J11: =ROUNDUP(I11,0) -> 25 | L11: 66 alakisko | M11: 1.8 | P11: Nauharuuvit | Q11: =$J$11*$M$30 -> 450 | R11: =$J$11*$M$30 -> 450 | S11: =$J$11*$M$30 -> 450 | T11: =$J$11*$M$30 -> 450 | U11: =$J$11*$M$30 -> 450 | V11: =$J$11*$M$30 -> 450 | W11: =$J$11*$M$30 -> 450 | X11: =$J$11*$M$30 -> 450 | Y11: 1-kertainen | Z11: 30.96 | AA11: =B11 -> 0 | AB11: =Z11*AA11 -> 0
A12: 2-kertainen | G12: Runkokiinnike, kpl | H12: =(H9*0.4)*1.1 -> 137.18738 | L12: 66 kertopuu | M12: 3.1 | P12: Runkokiinnike | Q12: =B32*$M$26 -> 320 | R12: =B32*$M$26 -> 320 | S12: =B32*$M$26 -> 320 | T12: =B32*$M$26 -> 320 | U12: =B32*$M$26 -> 320 | V12: =B32*$M$26 -> 320 | W12: =B32*$M$26 -> 320 | X12: =B32*$M$26 -> 320 | Y12: 2-kertainen | Z12: 40.32 | AA12: =B12 -> 0 | AB12: =Z12*AA12 -> 0
G13: Vahvike, esim kertopuu, metrit | H13: =(8*B18+B29)*1.1 -> 110 | L13: 95 ranka | M13: 1.8 | P13: Vahvike | Q13: =+H13*$M$12 -> 341 | R13: =+H13*$M$15 -> 357.5 | S13: =+H13*$M$12 -> 341 | T13: =+H13*$M$12 -> 341 | U13: =+H13*$M$12 -> 341 | V13: =+H13*$M$15 -> 357.5 | W13: =+H13*$M$12 -> 341 | X13: =+H13*$M$12 -> 341
A14: Pelkkä levytys | G14: Ovivahvike ruuvit, kpl | H14: =(B18*6) -> 0 | L14: 95 alakisko | M14: 2.1 | P14: Hobarit | Q14: =B33*$M$27 -> 100 | R14: =B33*$M$27 -> 100 | S14: =B33*$M$27 -> 100 | T14: =B33*$M$27 -> 100 | U14: =B33*$M$27 -> 100 | V14: =B33*$M$27 -> 100 | W14: =B33*$M$27 -> 100 | X14: =B33*$M$27 -> 100 | Y14: Pelkkä levytys | Z14: 16.2 | AA14: =B14 -> 0 | AB14: =Z14*AA14 -> 0
A15: Pelkkä vaneri | G15: Kertopuurunko, kiinnikkeet esim hobau 90mm, kpl | H15: =H9/0.3 -> 1039.2983 | L15: 92 keropuu | M15: 3.25 | P15: Akryyli | Q15: =H20*$M$28 -> 616.66667 | R15: =H20*$M$28 -> 616.66667 | S15: =H20*$M$28 -> 616.66667 | T15: =H20*$M$28 -> 616.66667 | U15: =H20*$M$28 -> 616.66667 | V15: =H20*$M$28 -> 616.66667 | W15: =H20*$M$28 -> 616.66667 | X15: =H20*$M$28 -> 616.66667 | Y15: Pelkkä vaneri | Z15: 18 | AA15: =B15 -> 0 | AB15: =Z15*AA15 -> 0
G16: GK-kannatus | H16: =B23*1.1 -> 0 | L16: Väliseinävilla | M16: 3.4 | P16: Vaneri | Q16: =B15*(18*0.014)*$M$25*1.1 -> 0 | R16: =B15*$M$25*1.1 -> 0 | S16: =B15*$M$25*1.1 -> 0 | T16: =B15*$M$25*1.1 -> 0 | U16: =B15*$M$25*1.1 -> 0 | V16: =B15*$M$25*1.1 -> 0 | W16: =B15*$M$25*1.1 -> 0 | X16: =B15*$M$25*1.1 -> 0 | Y16: Kotelo, m2 | Z16: 18.5 | AA16: =B23 -> 0 | AB16: =Z16*AA16 -> 0
B17: kpl | G17: SAUMAUS | H17: Litrat | I17: 10l purkki | L17: 120 ranka | M17: 2.2 | P17: Pientarvikkeet | Q17: =$B$34 -> 500 | R17: =$B$34 -> 500 | S17: =$B$34 -> 500 | T17: =$B$34 -> 500 | U17: =$B$34 -> 500 | V17: =$B$34 -> 500 | W17: =$B$34 -> 500 | X17: =$B$34 -> 500 | Y17: Kotelo, jm | Z17: 11.98 | AA17: =B24 -> 0 | AB17: =Z17*AA17 -> 0
A18: Ovi, max M10 | G18: J | H18: =(((B7+B8+B11+B12+B23)*2)*0.25*0.3)+(B14*0.32*1.1) -> 50.25 | I18: =H18/10 -> 5.025 | L18: 120 alakisko | M18: 2.3 | P18: J | Q18: =+I18*$M$23 -> 143.715 | R18: =+I18*$M$23 -> 143.715 | S18: =+I18*$M$23 -> 143.715 | T18: =+I18*$M$23 -> 143.715 | U18: =+I18*$M$23 -> 143.715 | V18: =+I18*$M$23 -> 143.715 | W18: =+I18*$M$23 -> 143.715 | X18: =+I18*$M$23 -> 143.715 | Y18: Ovi, max M10 | Z18: 16.38 | AA18: =B18 -> 0 | AB18: =Z18*AA18 -> 0
G19: LF | H19: =(((B7+B8+B11+B12+B23)*2)*0.25*0.3)+(B14*0.32*1.1) -> 50.25 | I19: =H19/10 -> 5.025 | L19: XR66 ranka | M19: 1.9 | P19: LF | Q19: =+I19*$M$24 -> 129.29325 | R19: =+I19*$M$24 -> 129.29325 | S19: =+I19*$M$24 -> 129.29325 | T19: =+I19*$M$24 -> 129.29325 | U19: =+I19*$M$24 -> 129.29325 | V19: =+I19*$M$24 -> 129.29325 | W19: =+I19*$M$24 -> 129.29325 | X19: =+I19*$M$24 -> 129.29325
B20: Pituus | C20: Korkeus | G20: Akryyli | H20: =B26/3 -> 166.66667 | L20: Acounomic 66 kisko | M20: 4.4 | P20: GK-kannatus | Q20: =$H$16*$M$29 -> 0 | R20: =$H$16*$M$29 -> 0 | S20: =$H$16*$M$29 -> 0 | T20: =$H$16*$M$29 -> 0 | U20: =$H$16*$M$29 -> 0 | V20: =$H$16*$M$29 -> 0 | W20: =$H$16*$M$29 -> 0 | X20: =$H$16*$M$29 -> 0
A21: Seinäke tai otsa, k-600 | B21: 30 | C21: 1.2 | G21: YLITASOITUS, 2mm kerros | H21: kg | I21: 20kg säkki | L21: XR95 ranka | M21: 2.1 | Y21: Seinäke tai otsa, k-600 | Z21: 37.44 | AA21: =B21 -> 30 | AB21: =Z21*AA21 -> 1123.2
G22: L | H22: =(B7+B8+B11+B12)*2*2.4 -> 1608 | I22: =H22/20 -> 80.4 | L22: Acounomic 95 kisko | M22: 4.6
A23: Kotelo, m2 | G23: LR+ | H23: =(B7+B8+B11+B12)*2*2.4 -> 1608 | I23: =H23/20 -> 80.4 | L23: Teknos J | M23: 28.6 | Y23: Kotelo, m2
A24: Kotelo, jm | G24: LF tai vastaava viimeistely, l / 10l purkki | H24: =(B7+B8+B11+B12)*2*0.6 -> 402 | I24: =H24/10 -> 40.2 | L24: Teknos LF | M24: 25.73 | Y24: Kotelo, jm | AA24: =B26 -> 500
B25: jm | L25: 12mm havuvaneri | M25: 11.5
A26: Akryyli | B26: 500 | L26: Spit pulsa naula + kaasu | M26: 80 | Y26: Akryyli
A27: tiivistykset, läpiviennit | L27: Hobarit 90mm | M27: 20 | Y27: tiivistykset, läpiviennit
B28: jm | L28: Akryyli | M28: 3.7
A29: Vahvike, kertop. | B29: 100 | L29: GK-kannattimet, m2 | M29: 15.5 | Y29: Vahvike, kertop. | Z29: 1.7 | AA29: =B29 -> 100 | AB29: =Z29*AA29 -> 170
A30: esim. lasiaukko | L30: Nauharuuvit | M30: 18 | Q30: =SUM(Q7:Q20) -> 11803.37 | R30: =SUM(R7:R20) -> 12117.498 | S30: =SUM(S7:S20) -> 12886.144 | T30: =SUM(T7:T20) -> 13084.562 | U30: =SUM(U7:U20) -> 17550.21 | V30: =SUM(V7:V20) -> 17864.338 | W30: =SUM(W7:W20) -> 18632.984 | X30: =SUM(X7:X20) -> 18831.402
AB31: =SUM(AB7:AB29) -> 13835.6
A32: Runkokiinnikkeet | B32: 4 | C32: Spit Pulsa naulat 500 kpl + kaasut, 75€ setti | Q32: EK - 66 LPR | R32: =Q30/((100-B38)/100) -> 11803.37
A33: Hobarit | B33: 5 | C33: 4,2x90mm, 500 kpl / rasia | Q33: EK - 90 LPR | R33: =R30/((100-B38)/100) -> 12117.498
A34: Pientarvikkeet | B34: 500 | C34: Summa, € | Q34: EK - 66 XR | R34: =S30/((100-B38)/100) -> 12886.144
Q35: EK - 90 XR | R35: =T30/((100-B38)/100) -> 13084.562
Q36: EK+VANERI- 66 LPR | R36: =U30/((100-B38)/100) -> 17550.21
A37: Hinta, Materiaalit | B37: EK - 66 XR | C37: =SUMIF(Q32:Q39,B37,R32:R39) -> 12886.144 | Q37: EK+VANERI- 90 LPR | R37: =V30/((100-B38)/100) -> 17864.338
A38: Kate-% | Q38: EK+VANERI- 66 XR | R38: =W30/((100-B38)/100) -> 18632.984
Q39: EK+VANERI- 90 XR | R39: =X30/((100-B38)/100) -> 18831.402
A40: Työ | C40: =AB31*((100+B41)/100) -> 13835.6
...

Sheet Maalaukset
A1: Tasoitukset ja maalaukset
A3: POS-1 | B3: Kuvaus
A4: Maalaus | B4: Kaikki seinät 3000 | K4: Menekki | Q4: sos 80% hinnoissa
B5: m2 / jm | H5: Tuote | I5: Menekki | J5: Tuote | K5: Menekki ylös pyör. | L5: Hinta, sk/pnt/rll | N5: Hinta | Q5: Työ | R5: Yht.
A6: Teippaus | B6: 1500 | G6: Sininen teippi | I6: =(B6/50)*1.1 -> 33 | J6: Teippi, rll | K6: =ROUNDUP(I6,0) -> 33 | L6: 11.26 | N6: =K6*L6 -> 371.58 | P6: Teippi + 1/4 imurointi | Q6: 1.25 | R6: =B6*Q6 -> 1875
A8: Osittain tasoitus, LG | G8: 0,4kg | H8: LW | I8: =(B8*0.4)/10 -> 0 | K8: =ROUNDUP(I8,0) -> 0 | L8: 41.1 | N8: =K8*L8 -> 0 | P8: Osittelu | Q8: 0.72 | R8: =B8*Q8 -> 0
A9: Osittainen tasoitus, LF | P9: Osittelu | Q9: 0.72 | R9: =B9*Q9 -> 0
R10: =B10*Q10 -> 0
A11: Ylitasoitus | C11: 1mm kerros / L ja LR+, voi laske neliöt X 2-3 | G11: Ylitasoitus n. 3mm, kilohinta | H11: L | I11: =(B11*1.2)/20 -> 0 | J11: Vetonit L | K11: =ROUNDUP(I11,0) -> 0 | L11: 11.9 | N11: =K11*L11 -> 0 | P11: Ylitasotus | Q11: 3.96 | R11: =B11*Q11 -> 0
H12: LR+ | I12: =(B11*1.2)/20 -> 0 | J12: Veotnit LR+ | K12: =ROUNDUP(I12,0) -> 0 | L12: 13.12 | N12: =K12*L12 -> 0 | R12: =B12*Q12 -> 0
A13: Rappauskorjaus, 10mm asti | P13: Rappaus | Q13: 28.98 | R13: =B13*Q13 -> 0
G14: 0,3kg / m2 osittaisessa | H14: LF | I14: =(B9*0.4)/10 -> 0 | J14: Teknos LF | K14: =ROUNDUP(I14,0) -> 0 | L14: 25.73 | N14: =K14*L14 -> 0 | R14: =B14*Q14 -> 0
A15: Pohjamaalaus 2X | B15: =850+380 -> 1230 | P15: Pohjamaal + hiomaal | Q15: 3.06 | R15: =B15*Q15 -> 3763.8
A16: Pintamaalaus 2X, maalarinv. | B16: 650 | G16: 10mm rappauskerros | H16: Goldband | I16: =(B13*12)/20 -> 0 | J16: Goldband | K16: =ROUNDUP(I16,0) -> 0 | L16: 15.07 | N16: =K16*L16 -> 0 | P16: Pintamaal 2X | Q16: 3.06 | R16: =B16*Q16 -> 1989
A17: Pintamaalaus 2X, sävytetty | B17: 200 | P17: Pintamaal 2X | Q17: 3.06 | R17: =B17*Q17 -> 612
G18: Pohjamaali, 6m2/l | H18: siro 2 | I18: =(B15*2*0.222222)/18 -> 30.37034 | J18: Siro 2 | K18: =ROUNDUP(I18,0) -> 31 | L18: 43 | N18: =K18*L18 -> 1333 | R18: =B18*Q18 -> 0
A19: Erillismaalit | C19: Purkkihinta, € | D19: Kuvaus | E19: Tuote | F19: Purkin koko, l | R19: =B19*Q19 -> 0
A20: Maali 1 X2 | F20: 0,1 | G20: Pintamaali MV, 6m2 / l | H20: Siro 7 mv | I20: =(B16*2*0.222222)/18 -> 16.049367 | J20: Siro 7 mv, 18l | K20: =ROUNDUP(I20,0) -> 17 | L20: 65 | N20: =K20*L20 -> 1105 | R20: =B20*Q20 -> 0
A21: Maali 2 X2 | F21: 0,1 | G21: Pintamaali + sävytys 6m2/l | H21: Nova C | I21: =(B17*2*0.222222)/18 -> 4.9382667 | J21: Nova C + sävy | K21: =ROUNDUP(I21,0) -> 5 | L21: 149 | N21: =K21*L21 -> 745 | R21: =B21*Q21 -> 0
A22: Maali 3 X2 | F22: 0,1 | R22: =B22*Q22 -> 0
C23: Purkkihintaan vain 1 purkin hinta, ohjelma laskee menekin itse | G23: Maali 1 | I23: =((B20*2)*0.22222)/F20 -> 0 | J23: Maali 1 | K23: =ROUNDUP(I23,0) -> 0 | L23: =C20 -> 0 | N23: =K23*L23 -> 0 | Q23: 3.06 | R23: =B20*Q23 -> 0
A24: Pientarvikkeet, € | B24: 500 | G24: Maali 2 | I24: =((B21*2)*0.22222)/F21 -> 0 | J24: Maali 2 | K24: =ROUNDUP(I24,0) -> 0 | L24: =C21 -> 0 | N24: =K24*L24 -> 0 | Q24: 3.06 | R24: =B21*Q24 -> 0
B25: 0 | G25: Maali 3 | I25: =((B22*2)*0.22222)/F22 -> 0 | J25: Maali 3 | K25: =ROUNDUP(I25,0) -> 0 | L25: =C22 -> 0 | N25: =K25*L25 -> 0 | Q25: 3.06 | R25: =B22*Q25 -> 0
A27: Hinta, materiaalit | B27: =N30/((100-B28)/100) -> 4505.0889
A28: Kate | B28: 10 | G28: Pientarvikkeet | N28: =B24 -> 500
A30: Työ | B30: =R30*((100+B31)/100) -> 8239.8 | N30: =SUM(N6:N28) -> 4054.58 | R30: =SUM(R6:R29) -> 8239.8
A31: Lisä-%
A33: Yht. | B33: =B27+B30 -> 12744.889
A36: POS-2 | B36: Kuvaus
A37: Maalaus | B37: wc etutilan maalaukset
B38: m2 / jm | H38: Tuote | I38: Menekki | J38: Tuote | K38: Menekki ylös pyör. | L38: Hinta, sk/pnt/rll | N38: Hinta | Q38: Työ | R38: Yht.
A39: Teippaus | G39: Sininen teippi | I39: =(B39/50)*1.1 -> 0 | K39: =ROUNDUP(I39,0) -> 0 | L39: 11.26 | N39: =K39*L39 -> 0 | P39: Teippi + 1/4 imurointi | Q39: 1.25 | R39: =B39*Q39 -> 0
A41: Osittain tasoitus, LG | G41: 0,4kg | H41: LW | I41: =(B41*0.4)/10 -> 0 | K41: =ROUNDUP(I41,0) -> 0 | L41: 41.1 | N41: =K41*L41 -> 0 | P41: Osittelu | Q41: 0.72 | R41: =B41*Q41 -> 0
A42: Osittainen tasoitus, LF | P42: Osittelu | Q42: 0.72 | R42: =B42*Q42 -> 0
R43: =B43*Q43 -> 0
A44: Ylitasoitus | C44: 1mm kerros / L ja LR+, voi laske neliöt X 2-3 | G44: Ylitasoitus n. 3mm, kilohinta | H44: L | I44: =(B44*1.2)/20 -> 0 | J44: Vetonit L | K44: =ROUNDUP(I44,0) -> 0 | L44: 11.9 | N44: =K44*L44 -> 0 | P44: Ylitasotus | Q44: 3.96 | R44: =B44*Q44 -> 0
H45: LR+ | I45: =(B44*1.2)/20 -> 0 | J45: Veotnit LR+ | K45: =ROUNDUP(I45,0) -> 0 | L45: 13.12 | N45: =K45*L45 -> 0 | R45: =B45*Q45 -> 0
A46: Rappauskorjaus, 10mm asti | P46: Rappaus | Q46: 28.98 | R46: =B46*Q46 -> 0
G47: 0,3kg / m2 osittaisessa | H47: LF | I47: =(B42*0.4)/10 -> 0 | J47: Teknos LF | K47: =ROUNDUP(I47,0) -> 0 | L47: 25.73 | N47: =K47*L47 -> 0 | R47: =B47*Q47 -> 0
A48: Pohjamaalaus 2X | B48: 35 | P48: Pohjamaal + hiomaal | Q48: 3.06 | R48: =B48*Q48 -> 107.1
...

Sheet Alakatot
A1: Alakattoasennukset
A3: POS-1 | B3: Kuvaus
A4: Alakattoasennus | B4: Katon akustointi 75%
G5: Materiaali | K5: Työ
B6: Määrä, m2 | C6: Tuote | G6: Määrä | H6: Hinta | I6: Yht. | K6: Määrä | L6: Hinta | M6: Yht.
A7: Liimakiinnitys | B7: 190 | G7: =B7 -> 190 | H7: =B8+3.4 -> 26.4 | I7: =G7*H7 -> 5016 | K7: =B7 -> 190 | L7: 12 | M7: =K7*L7 -> 2280
A8: Tuotteen hinta / m2 | B8: 23 | C8: Ecophon DS frost white, 600x1200x40 | G8: =B8 -> 23 | I8: =G8*H8 -> 0 | M8: =K8*L8 -> 0
M9: =K9*L9 -> 0
A10: T-15, T-24, normi | G10: =B10 -> 0 | H10: 5.5 | I10: =G10*H10 -> 0 | K10: =B10 -> 0 | L10: 15.12 | M10: =K10*L10 -> 0
A11: Tuotteen hinta / m2 | C11: Ecophon DS A-reuna | G11: =B10 -> 0 | H11: =B11 -> 0 | I11: =G11*H11 -> 0 | M11: =K11*L11 -> 0
M12: =K12*L12 -> 0
A13: T-15, T-24, piiloasennus | G13: =B13 -> 0 | H13: 5.5 | I13: =G13*H13 -> 0 | K13: =B13 -> 0 | L13: 18 | M13: =K13*L13 -> 0
A14: Tuotteen hinta / m2 | C14: Ecophon FG E-reuna | G14: =B13 -> 0 | H14: =B14 -> 0 | I14: =G14*H14 -> 0 | M14: =K14*L14 -> 0
M15: =K15*L15 -> 0
A16: SK (ripustuskisko) + GN13 | G16: =B16 -> 0 | H16: 17 | I16: =G16*H16 -> 0 | K16: =B16 -> 0 | L16: 27.9 | M16: =K16*L16 -> 0
A17: Kiinteä runko | G17: =B17*4 -> 0 | H17: 2.4 | I17: =G17*H17 -> 0 | K17: =B17 -> 0 | L17: 25.1 | M17: =K17*L17 -> 0
A18: Runko hinta / m | C18: esim kertopuu, metalliranka | M18: =K18*L18 -> 0
M19: =K19*L19 -> 0
A20: Kiinteä kipsilevykatto | G20: =B20 -> 0 | H20: =B21 -> 0 | I20: =G20*H20*1.1 -> 0 | M20: =K20*L20 -> 0
A21: Levyn hinta / m2 | M21: =K21*L21 -> 0
M22: =K22*L22 -> 0
A23: Pientarvikkeet € | B23: 500 | I23: =B23 -> 500 | M23: =K23*L23 -> 0
H25: yht. | I25: =SUM(I7:I23) -> 5516 | L25: yht. | M25: =SUM(M7:M24) -> 2280
A26: Hinta, materiaalit | B26: =I25/((100-B27)/100) -> 5516
A27: Kate-% | B27: 0
A29: Hinta, Työ | B29: =M25*((100+B30)/100) -> 2850
A30: Lisä-% | B30: 25
A33: POS-2 | B33: Kuvaus
A34: Alakattoasennus | B34: T-24 yleensä
G35: Materiaali | K35: Työ
B36: Määrä, m2 | C36: Tuote | G36: Määrä | H36: Hinta | I36: Yht. | K36: Määrä | L36: Hinta | M36: Yht.
A37: Liimakiinnitys | G37: =B37 -> 0 | H37: =B38+3.4 -> 3.4 | I37: =G37*H37 -> 0 | K37: =B37 -> 0 | L37: 12 | M37: =K37*L37 -> 0
A38: Tuotteen hinta / m2 | C38: Ecophon DS frost white, 600x1200x40 | G38: =B38 -> 0 | I38: =G38*H38 -> 0 | M38: =K38*L38 -> 0
M39: =K39*L39 -> 0
A40: T-15, T-24, normi | B40: 70 | G40: =B40 -> 70 | H40: 5.5 | I40: =G40*H40 -> 385 | K40: =B40 -> 70 | L40: 20 | M40: =K40*L40 -> 1400
A41: Tuotteen hinta / m2 | B41: 23 | C41: Ecophon DS A-reuna | G41: =B40 -> 70 | H41: =B41 -> 23 | I41: =G41*H41 -> 1610 | M41: =K41*L41 -> 0
M42: =K42*L42 -> 0
A43: T-15, T-24, piiloasennus | G43: =B43 -> 0 | H43: 5.5 | I43: =G43*H43 -> 0 | K43: =B43 -> 0 | L43: 25 | M43: =K43*L43 -> 0
A44: Tuotteen hinta / m2 | C44: Ecophon FG E-reuna | G44: =B43 -> 0 | H44: =B44 -> 0 | I44: =G44*H44 -> 0 | M44: =K44*L44 -> 0
M45: =K45*L45 -> 0
...

Sheet Laatoitukset
A1: Laatoitukset
A3: POS-1 | B3: Kuvaus
A4: Laatoitukset | B4: seinien laatoitus
H5: Materiaali | L5: Työ | P5: Menekki
B6: Määrä, m2 | C6: Tuote | D6: Hukka-% | H6: Määrä | I6: Hinta | J6: Yht. | L6: Määrä | M6: Hinta | N6: Yht. | P6: kg | Q6: yksikkö, esim säkki | R6: Pyöristys täyteen
A7: Laatoitus, kuivat tilat | H7: =B7 -> 0 | I7: =(B8*(D8/100+1))+3 -> 3 | J7: =H7*I7 -> 0 | L7: =B7 -> 0 | M7: 38 | N7: =L7*M7 -> 0 | O7: Vetonit Rex Fix | P7: =B7*3 -> 0 | Q7: =P7/20 -> 0 | R7: =ROUNDUP(Q7,0) -> 0
A8: Tuotteen hinta / m2 | D8: 10 | J8: =H8*I8 -> 0 | N8: =L8*M8 -> 0 | R8: =ROUNDUP(Q8,0) -> 0
N9: =L9*M9 -> 0 | R9: =ROUNDUP(Q9,0) -> 0
A10: Laatoitus, kosteat tilat | B10: 65 | H10: =B10 -> 65 | I10: =(B11*(D11/100+1))+3 -> 47 | J10: =H10*I10 -> 3055 | L10: =B10 -> 65 | M10: 38 | N10: =L10*M10 -> 2470 | O10: Vetonit Rex Fix | P10: =B10*3 -> 195 | Q10: =P10/20 -> 9.75 | R10: =ROUNDUP(Q10,0) -> 10
A11: Tuotteen hinta / m2 | B11: 40 | C11: Stark VV57, 20x40 mattavalk. | D11: 10 | N11: =L11*M11 -> 0 | R11: =ROUNDUP(Q11,0) -> 0
N12: =L12*M12 -> 0 | R12: =ROUNDUP(Q12,0) -> 0
A13: Laatoitus kosteat tilat, sis. Vesieristys -> sauman pesu | E13: Työn osuus + laatan hinta | H13: =B13 -> 0 | I13: =(B14*(D14/100+1)) -> 0 | J13: =H13*I13 -> 0 | L13: =B13 -> 0 | M13: 75 | N13: =L13*M13 -> 0 | O13: Vetonit Rex Fix | P13: =B13*3 -> 0 | Q13: =P13/20 -> 0 | R13: =ROUNDUP(Q13,0) -> 0
A14: Tuotteen hinta / m2 | D14: 10 | N14: =L14*M14 -> 0 | R14: =ROUNDUP(Q14,0) -> 0
N15: =L15*M15 -> 0 | R15: =ROUNDUP(Q15,0) -> 0
A16: Vesieriste | B16: 65 | H16: 1 | I16: =B16*1.8*7.14 -> 835.38 | J16: =H16*I16 -> 835.38 | L16: =B16 -> 65 | M16: 14.04 | N16: =L16*M16 -> 912.6 | O16: Vetonit WP 15l | P16: =B16*1.8 -> 117 | Q16: =P16/15 -> 7.8 | R16: =ROUNDUP(Q16,0) -> 8
N17: =L17*M17 -> 0 | R17: =ROUNDUP(Q17,0) -> 0
A18: Vesieristenauha | B18: 180 | H18: =B18 -> 180 | I18: 0.51 | J18: =H18*I18*1.1 -> 100.98 | L18: =B18 -> 180 | M18: 2.8 | N18: =L18*M18 -> 504 | O18: Vedeneristenauha | P18: =B18 -> 180 | Q18: =P18/40 -> 4.5 | R18: =ROUNDUP(Q18,0) -> 5
N19: =L19*M19 -> 0 | R19: =ROUNDUP(Q19,0) -> 0
A20: Kaivolaippa | B20: 8 | H20: =B20 -> 8 | I20: =10.35 -> 10.35 | J20: =H20*I20 -> 82.8 | L20: =B20 -> 8 | M20: 4.4 | N20: =L20*M20 -> 35.2 | O20: Kaivolaippa | Q20: =B20 -> 8 | R20: =ROUNDUP(Q20,0) -> 8
N21: =L21*M21 -> 0 | R21: =ROUNDUP(Q21,0) -> 0
A22: Läpivientivahvike | B22: 30 | H22: =B22 -> 30 | I22: 10.42 | J22: =H22*I22 -> 312.6 | L22: =B22 -> 30 | M22: 2.8 | N22: =L22*M22 -> 84 | O22: Läpivientivahvike | Q22: =B22 -> 30 | R22: =ROUNDUP(Q22,0) -> 30
A24: Saumalaasti, neliöt | B24: 65 | H24: =B24 -> 65 | I24: 3.17 | J24: =H24*I24 -> 206.05 | L24: =B24 -> 65 | M24: 5.3 | N24: =L24*M24 -> 344.5 | O24: Saumalaasti | P24: =B24/1.5 -> 43.333333 | Q24: =P24/10 -> 4.3333333 | R24: =ROUNDUP(Q24,0) -> 5
A26: Pientarvikkeet € | B26: 500 | I26: =(B27*(D27/100+1)) -> 0 | J26: =B26 -> 500
I28: yht. | J28: =SUM(J7:J26) -> 5092.81 | M28: yht. | N28: =SUM(N7:N27) -> 4350.3
A29: Hinta, materiaalit | B29: =J28/((100-B30)/100) -> 5092.81
A30: Kate-% | B30: 0
A32: Hinta, Työ | B32: =N28*((100+B33)/100) -> 4350.3
A33: Lisä-%
A36: POS-2 | B36: Kuvaus
A37: Laatoitukset | B37: lattian laatoitus
H38: Materiaali | L38: Työ | P38: Menekki
B39: Määrä, m2 | C39: Tuote | D39: Hukka-% | H39: Määrä | I39: Hinta | J39: Yht. | L39: Määrä | M39: Hinta | N39: Yht. | P39: kg | Q39: yksikkö, esim säkki | R39: Pyöristys täyteen
A40: Laatoitus, kuivat tilat | H40: =B40 -> 0 | I40: =(B41*(D41/100+1))+3 -> 3 | J40: =H40*I40 -> 0 | L40: =B40 -> 0 | M40: 38 | N40: =L40*M40 -> 0 | O40: Vetonit Rex Fix | P40: =B40*3 -> 0 | Q40: =P40/20 -> 0 | R40: =ROUNDUP(Q40,0) -> 0
A41: Tuotteen hinta / m2 | D41: 10 | J41: =H41*I41 -> 0 | N41: =L41*M41 -> 0 | R41: =ROUNDUP(Q41,0) -> 0
N42: =L42*M42 -> 0 | R42: =ROUNDUP(Q42,0) -> 0
A43: Laatoitus, kosteat tilat | B43: 17 | H43: =B43 -> 17 | I43: =(B44*(D44/100+1))+3 -> 3 | J43: =H43*I43 -> 51 | L43: =B43 -> 17 | M43: 38 | N43: =L43*M43 -> 646 | O43: Vetonit Rex Fix | P43: =B43*3 -> 51 | Q43: =P43/20 -> 2.55 | R43: =ROUNDUP(Q43,0) -> 3
A44: Tuotteen hinta / m2 | C44: Vakioharmaa, stark | D44: 10 | N44: =L44*M44 -> 0 | R44: =ROUNDUP(Q44,0) -> 0
N45: =L45*M45 -> 0 | R45: =ROUNDUP(Q45,0) -> 0
A46: Laatoitus kosteat tilat, sis. Vesieristys -> sauman pesu | E46: Työn osuus + laatan hinta | H46: =B46 -> 0 | I46: =(B47*(D47/100+1)) -> 0 | J46: =H46*I46 -> 0 | L46: =B46 -> 0 | M46: 75 | N46: =L46*M46 -> 0 | O46: Vetonit Rex Fix | P46: =B46*3 -> 0 | Q46: =P46/20 -> 0 | R46: =ROUNDUP(Q46,0) -> 0
A47: Tuotteen hinta / m2 | D47: 10 | N47: =L47*M47 -> 0 | R47: =ROUNDUP(Q47,0) -> 0
...

Sheet Lattiat
A1: Lattia-asennukset
A2: POS-1 | B2: Kuvaus
A3: Lattiamateriaalit | B3: Palamatto | M3: sisältää 80% sos
H4: Materiaali | L4: Työ
B5: Määrä, m2 | C5: Tuote | D5: Hukka-% | H5: Määrä | I5: Hinta | J5: Yht. | L5: Määrä | M5: Hinta | N5: Yht.
A6: Liimakiinnitys | B6: 330 | E6: Vinyyli- ja tekstiilipalamatto | H6: =B6 -> 330 | I6: =(B7*(D7/100+1))+1 -> 39.5 | J6: =H6*I6 -> 13035 | L6: =B6 -> 330 | M6: 4.8 | N6: =L6*M6 -> 1584
A7: Tuotteen hinta / m2 | B7: 35 | D7: 10 | J7: =H7*I7 -> 0 | N7: =L7*M7 -> 0
N8: =L8*M8 -> 0
A9: Tarrakiinnitys | E9: Vinyyli- ja tekstiilipalamatto | H9: =B9 -> 0 | I9: =(B10*(D10/100+1))+1.5 -> 1.5 | J9: =H9*I9 -> 0 | L9: =B9 -> 0 | M9: 6.4 | N9: =L9*M9 -> 0
A10: Tuotteen hinta / m2 | D10: 10 | N10: =L10*M10 -> 0
N11: =L11*M11 -> 0
A12: Pontattu vinyyli | H12: =B12 -> 0 | I12: =(B13*(D13/100+1)) -> 0 | J12: =H12*I12 -> 0 | L12: =B12 -> 0 | M12: 10.8 | N12: =L12*M12 -> 0
A13: Tuotteen hinta / m2 | D13: 10 | N13: =L13*M13 -> 0
N14: =L14*M14 -> 0
A15: Pontattu parketti / laminaatti | H15: =B15 -> 0 | I15: =(B16*(D16/100+1)) -> 0 | J15: =H15*I15 -> 0 | L15: =B15 -> 0 | M15: 16 | N15: =L15*M15 -> 0
A16: Tuotteen hinta | D16: 10 | N16: =L16*M16 -> 0
N17: =L17*M17 -> 0
A18: Alusmaton asennus | H18: =B18 -> 0 | I18: =(B19*(D19/100+1)) -> 0 | J18: =H18*I18*1.1 -> 0 | L18: =B18 -> 0 | M18: 1.5 | N18: =L18*M18 -> 0
A19: Alusmateriaalin hinta | D19: 10 | N19: =L19*M19 -> 0
N20: =L20*M20 -> 0
A21: Laatoitus, kuiva tila | H21: =B21 -> 0 | I21: =(B22*(D22/100+1))+3 -> 3 | J21: =H21*I21 -> 0 | L21: =B21 -> 0 | M21: 38 | N21: =L21*M21 -> 0
A22: Tuotteen hinta | D22: 10 | N22: =L22*M22 -> 0
N23: =L23*M23 -> 0
A24: Lattian maalaus 1-K ja 2-K | E24: Huomioi myös menekki, hinta | H24: 1 | I24: =B25 -> 0 | J24: =H24*I24 -> 0 | L24: =B24 -> 0 | M24: 5.04 | N24: =L24*M24 -> 0
A25: Tuotteen hinta | E25: kohtaan koko tarvittava määrä
A27: Pientarvikkeet € | B27: 350 | I27: =(B28*(D28/100+1)) -> 0 | J27: =B27 -> 350 | N27: =L27*M27 -> 0
L28: =B28 -> 0
I29: yht. | J29: =SUM(J6:J27) -> 13385 | M29: yht. | N29: =SUM(N6:N28) -> 1584
A30: Hinta, materiaalit | B30: =J29/((100-B31)/100) -> 13385
A31: Kate-% | B31: 0
A33: Hinta, Työ | B33: =N29/((100-B34)/100) -> 1980
A34: Lisä-% | B34: 20
H36: Materiaali | L36: Työ
A37: POS-2 | B37: Kuvaus
A38: Lattiamateriaalit | B38: vinyyli
H39: Materiaali | L39: Työ
B40: Määrä, m2 | C40: Tuote | D40: Hukka-% | H40: Määrä | I40: Hinta | J40: Yht. | L40: Määrä | M40: Hinta | N40: Yht.
A41: Liimakiinnitys | E41: Vinyyli- ja tekstiilipalamatto | H41: =B41 -> 0 | I41: =(B42*(D42/100+1))+1 -> 1 | J41: =H41*I41 -> 0 | L41: =B41 -> 0 | M41: 4.8 | N41: =L41*M41 -> 0
A42: Tuotteen hinta / m2 | D42: 10 | J42: =H42*I42 -> 0 | N42: =L42*M42 -> 0
N43: =L43*M43 -> 0
...

Sheet Oviasennukset ja listoitukset
A1: Oviasennukset ja listoitukset
A3: POS-1 | B3: Kuvaus
A4: Oviasennukset ja lisotitukset | B4: Ovet ja listoitukset | L4: sos 80 % huomioitu hinnassa
B5: Jm / kpl | C5: Tuote | G5: Materiaali | K5: Työ
A6: Perus laakaovi + karmit ja kynnys listoitettuna | G6: Määrä | H6: Hinta | I6: Yht. | K6: Määrä | L6: Hinta | M6: Yht.
A7: Tuotteen hinta / m2 | B7: 205 | C7: Stark RAW | G7: =B6 -> 0 | H7: =B7 -> 205 | I7: =G7*H7 -> 0 | K7: =B6 -> 0 | L7: 49.86 | M7: =K7*L7 -> 0
I8: =G8*H8 -> 0 | M8: =K8*L8 -> 0
A9: Märkätila-laakaovi + karmit ja kynnys listoitettuna | M9: =K9*L9 -> 0
A10: Tuotteen hinta / m2 | C10: Swedoo Bath | G10: =B9 -> 0 | H10: =B10 -> 0 | I10: =G10*H10 -> 0 | K10: =B9 -> 0 | L10: 49.86 | M10: =K10*L10 -> 0
M11: =K11*L11 -> 0
A12: ÄE-laakaovi listoitettuna, 25dB (sis. Tiivistykset) | B12: 1 | M12: =K12*L12 -> 0
A13: Tuotteen hinta / m2 | B13: 1200 | C13: pariovi | G13: =B12 -> 1 | H13: =B13 -> 1200 | I13: =G13*H13 -> 1200 | K13: =B12 -> 1 | L13: 61.38 | M13: =K13*L13 -> 61.38
D14: Ovet karmeineen, ilman listoja tai heloja | M14: =K14*L14 -> 0
A15: Raskas ÄE-ovi listoitettuna, 38dB (sis. Tiivistyket) | B15: 17 | D15: Swedoor sound rw 30 dB | E15: =155+38+13 -> 206 | M15: =K15*L15 -> 0
A16: Tuotteen hinta / m2 | B16: 370 | C16: Jeld-wen Fire 810 | D16: Jeld-wen fire 810 Rw 37 dB | E16: 310 | G16: =B15 -> 17 | H16: =B16 -> 370 | I16: =G16*H16 -> 6290 | K16: =B15 -> 17 | L16: 61.38 | M16: =K16*L16 -> 1043.46
D17: Lahden ovi rw 42 dB | E17: 690 | M17: =K17*L17 -> 0
A18: Raska palo-ovi | M18: =K18*L18 -> 0
A19: Tuotteen hinta (syötä tarjoushinta) | G19: =B18 -> 0 | H19: =B19 -> 0 | I19: =G19*H19*1.1 -> 0 | K19: =B18 -> 0 | L19: 423 | M19: =K19*L19 -> 0
M20: =K20*L20 -> 0
A21: Jalkalista | B21: 350 | M21: =K21*L21 -> 0
A22: Tuotteen hinta | B22: 1.38 | C22: 12x42x3600 valk. Mänty | G22: =B21 -> 350 | H22: =B22 -> 1.38 | I22: =G22*H22 -> 483 | K22: =B21 -> 350 | L22: 2.5 | M22: =K22*L22 -> 875
M23: =K23*L23 -> 0
A24: Listoitus yleensä | B24: 100 | M24: =K24*L24 -> 0
A25: Tuotteen hinta | B25: 1.5 | G25: =B24 -> 100 | H25: =B25 -> 1.5 | I25: =G25*H25 -> 150 | K25: =B24 -> 100 | L25: 2.5 | M25: =K25*L25 -> 250
A27: Pientarvikkeet € | B27: 350
H28: =B27 -> 350 | I28: =B27 -> 350 | M28: =K28*L28 -> 0
K29: =B28 -> 0
A30: Hinta, materiaalit | B30: =I30/((100-B31)/100) -> 9414.4444 | C30: huomioitu kv-varausten työstöt | H30: yht. | I30: =SUM(I7:I28) -> 8473 | L30: yht. | M30: =SUM(M7:M29) -> 2229.84
A31: Kate-% | B31: 10
A33: Hinta, Työ | B33: =M30/((100-B34)/100) -> 2229.84
A34: Lisä-% | B34: 0
A37: POS-2 | B37: Kuvaus
A38: Oviasennukset ja lisotitukset | B38: pariovi
B39: Jm / kpl | C39: Tuote | G39: Materiaali | K39: Työ
A40: Perus laakaovi + karmit ja kynnys listoitettuna | G40: Määrä | H40: Hinta | I40: Yht. | K40: Määrä | L40: Hinta | M40: Yht.
A41: Tuotteen hinta / m2 | C41: Stark RAW | G41: =B40 -> 0 | H41: =B41 -> 0 | I41: =G41*H41 -> 0 | K41: =B40 -> 0 | L41: 49.86 | M41: =K41*L41 -> 0
I42: =G42*H42 -> 0 | M42: =K42*L42 -> 0
A43: Märkätila-laakaovi + karmit ja kynnys listoitettuna | M43: =K43*L43 -> 0
A44: Tuotteen hinta / m2 | C44: Swedoo Bath | G44: =B43 -> 0 | H44: =B44 -> 0 | I44: =G44*H44 -> 0 | K44: =B43 -> 0 | L44: 49.86 | M44: =K44*L44 -> 0
M45: =K45*L45 -> 0
...

Sheet Erillishankinnat
A1: Erillishankinnat
A3: POS-1 | B3: Kuvaus | C3: Hinta / Tarjous | D3: Urakoitsija / Toimittaja | E3: Tarjous nro.
A4: 1 | B4: Lasielementit | C4: =48*210 -> 10080 | H4: =A4 -> 1 | I4: =C4 -> 10080
B5: Kate-% | C5: 12 | H5: =A9 -> 2 | I5: =C9 -> 10000
B6: Kate-osuus | C6: =C4/((100-C5)/100)-C4 -> 1374.5455 | H6: =A14 -> 3 | I6: =C14 -> 5600
B7: Yht. | C7: =C4+C6 -> 11454.545 | H7: =A19 -> 4 | I7: =C19 -> 0
I8: =C24 -> 0
A9: 2 | B9: Yleissiivoukset ja loppusiivous | C9: 10000 | I9: =C29 -> 0
B10: Kate-% | C10: 12 | I10: =C34 -> 0
B11: Kate-osuus | C11: =C9/((100-C10)/100)-C9 -> 1363.6364 | I11: =C39 -> 0
B12: Yht. | C12: =C9+C11 -> 11363.636
A14: 3 | B14: 2 kpl aluprofiiliovet hissiaulaan | C14: =2800*2 -> 5600
B15: Kate-% | C15: 12
B16: Kate-osuus | C16: =C14/((100-C15)/100)-C14 -> 763.63636
B17: Yht. | C17: =C14+C16 -> 6363.6364
A19: 4
B20: Kate-% | C20: 12
B21: Kate-osuus | C21: =C19/((100-C20)/100)-C19 -> 0
B22: Yht. | C22: =C19+C21 -> 0
A24: 5
B25: Kate-% | C25: 8
B26: Kate-osuus | C26: =C24/((100-C25)/100)-C24 -> 0
B27: Yht. | C27: =C24+C26 -> 0
A29: 6
B30: Kate-% | C30: 18
B31: Kate-osuus | C31: =C29/((100-C30)/100)-C29 -> 0
B32: Yht. | C32: =C29+C31 -> 0
A34: 7
B35: Kate-% | C35: 18
B36: Kate-osuus | C36: =C34/((100-C35)/100)-C34 -> 0
B37: Yht. | C37: =C34+C36 -> 0
A39: 8
B40: Kate-% | C40: 18
B41: Kate-osuus | C41: =C39/((100-C40)/100)-C39 -> 0
B42: Yht. | C42: =C39+C41 -> 0
A44: 9
B45: Kate-% | C45: 18
B46: Kate-osuus | C46: =C44/((100-C45)/100)-C44 -> 0
B47: Yht. | C47: =C44+C46 -> 0
A49: 10
...

Sheet Eritelysivu
A1: Urakka | B1: Tekniikantie 4 2. krs.
A2: Tilaaja | B2: =Koontisivu!A12 -> 0
G4: Syötä hinnoitteluhinta tuntiarviota varten
A5: Koonti | F5: Hinnoitteluhinta n. | G5: 42
A7: Tuntihinnoittelut | B7: Hinta | C7: =Tuntihinnoittelut!C39 -> 12432 | E7: Väliseinät | F7: Materiaali | G7: Työ
B8: Tunnit | C8: =Tuntihinnoittelut!C37 -> 296 | E8: POS-1 | F8: ='Väliseinät sisällä'!C37 -> 12886.144 | G8: ='Väliseinät sisällä'!C40 -> 13835.6
B9: %-osuus urakasta | C9: =C7/B120 -> 0.23318407 | E9: POS-2 | F9: ='Väliseinät sisällä'!C82 -> 0 | G9: ='Väliseinät sisällä'!C85 -> 0
A10: Materiaalit | B10: Hinta | C10: =Materiaalihinnoittelut!F327 -> 4668 | E10: POS-3 | F10: ='Väliseinät sisällä'!C126 -> 0 | G10: ='Väliseinät sisällä'!C129 -> 0
A11: Kate-% | C11: 15 | E11: POS-4 | F11: ='Väliseinät sisällä'!C169 -> 0 | G11: ='Väliseinät sisällä'!C172 -> 0
A12: Kate-osuus | C12: =(C10/((100-C11)/100))-C10 -> 823.76471 | E12: POS-5 | F12: ='Väliseinät sisällä'!C212 -> 0 | G12: ='Väliseinät sisällä'!C215 -> 0
E13: POS-6 | F13: ='Väliseinät sisällä'!C255 -> 0 | G13: ='Väliseinät sisällä'!C258 -> 0
A14: Hinta, materiaalit | C14: =C10+C12 -> 5491.7647 | E14: POS-7 | F14: ='Väliseinät sisällä'!C298 -> 0 | G14: ='Väliseinät sisällä'!C301 -> 0
E15: POS-8 | F15: ='Väliseinät sisällä'!C341 -> 0 | G15: ='Väliseinät sisällä'!C344 -> 0
A17: Purkutyöt | B17: Materiaali | C17: Työ
A18: POS-1 | C18: =Purkutyöt!C7 -> 0
A19: POS-2 | B19: =Purkutyöt!C38 -> 4330 | C19: =Purkutyöt!C36 -> 1680
A21: Yhteensö | B21: =SUM(B18:B19) -> 4330 | C21: =SUM(C18:C20) -> 1680 | E21: Yhteensä | F21: =SUM(F8:F16) -> 12886.144 | G21: =SUM(G8:G16) -> 13835.6
A22: Kate-% | B22: 20 | C22: 15 | E22: Kate-% | F22: 20 | G22: 15
A23: Kate-osuus | B23: =(B21/((100-B22)/100))-B21 -> 1082.5 | C23: =(C21/((100-C22)/100))-C21 -> 296.47059 | E23: Kate-osuus | F23: =F21/((100-F22)/100)-F21 -> 3221.536 | G23: =G21/((100-G22)/100)-G21 -> 2441.5765
A25: Hinta, purkutyöt | B25: =B21+B23 -> 5412.5 | C25: =C21+C23 -> 1976.4706 | E25: Hinta, väliseinät | F25: =F21+F23 -> 16107.68 | G25: =G21+G23 -> 16277.176
A26: %-osuus urakasta | C26: =C25/B120 -> 0.037072189 | E26: %-osuus urakasta | G26: =G21/B120 -> 0.25951106
A27: Purkutyöt, tunnit | C27: =C25/G5 -> 47.058824 | E27: Väliseinät tunnit | G27: =G25/G5 -> 387.55182
A30: Maalaukset | B30: Materiaali | C30: Työ | E30: Alakatot | F30: Materiaali | G30: Työ
A31: POS-1 | B31: =Maalaukset!B27 -> 4505.0889 | C31: =Maalaukset!B30 -> 8239.8 | E31: POS-1 | F31: =Alakatot!B26 -> 5516 | G31: =Alakatot!B29 -> 2850
A32: POS-2 | B32: =Maalaukset!B60 -> 801.16 | C32: =Maalaukset!B63 -> 267.75 | E32: POS-2 | F32: =Alakatot!B56 -> 2345 | G32: =Alakatot!B59 -> 2100
A33: POS-3 | B33: =Maalaukset!B93 -> 0 | C33: =Maalaukset!B96 -> 0 | E33: POS-3 | F33: =Alakatot!B86 -> 0 | G33: =Alakatot!B89 -> 0
A34: POS-4 | B34: =Maalaukset!B126 -> 0 | C34: =Maalaukset!B129 -> 0 | E34: POS-4 | F34: =Alakatot!B116 -> 0 | G34: =Alakatot!B119 -> 0
A35: POS-5 | B35: =Maalaukset!B159 -> 0 | C35: =Maalaukset!B162 -> 0 | E35: POS-5 | F35: =Alakatot!B146 -> 0 | G35: =Alakatot!B149 -> 0
A36: POS-6 | B36: =Maalaukset!B192 -> 0 | C36: =Maalaukset!B195 -> 0 | E36: POS-6 | F36: =Alakatot!B176 -> 0 | G36: =Alakatot!B179 -> 0
A37: POS-7 | B37: =Maalaukset!B225 -> 0 | C37: =Maalaukset!B228 -> 0 | E37: POS-7 | F37: =Alakatot!B206 -> 0 | G37: =Alakatot!B209 -> 0
A38: POS-8 | B38: =Maalaukset!B258 -> 0 | C38: =Maalaukset!B261 -> 0 | E38: POS-8 | F38: =Alakatot!B236 -> 0 | G38: =Alakatot!B239 -> 0
A39: POS-9 | B39: =Maalaukset!B291 -> 0 | C39: =Maalaukset!B294 -> 0
A40: POS-10 | B40: =Maalaukset!B324 -> 0 | C40: =Maalaukset!B327 -> 0 | E40: Yhteensä | F40: =SUM(F31:F39) -> 7861 | G40: =SUM(G31:G39) -> 4950
A41: POS-11 | B41: =Maalaukset!B357 -> 0 | C41: =Maalaukset!B360 -> 0 | E41: Kate-% | F41: 20 | G41: 15
A42: POS-12 | B42: =Maalaukset!B390 -> 0 | C42: =Maalaukset!B393 -> 0 | E42: Kate-osuus | F42: =F40/((100-F41)/100)-F40 -> 1965.25 | G42: =G40/((100-G41)/100)-G40 -> 873.52941
A44: Yhteensä | B44: =SUM(B31:B43) -> 5306.2489 | C44: =SUM(C31:C43) -> 8507.55 | E44: Hinta, alakatot | F44: =F40+F42 -> 9826.25 | G44: =G40+G42 -> 5823.5294
A45: Kate-% | B45: 20 | C45: 15 | E45: %-osuus urakasta | G45: =G40/B120 -> 0.092845972
A46: Kate-osuus | B46: =B44/((100-B45)/100)-B44 -> 1326.5622 | C46: =C44/((100-C45)/100)-C44 -> 1501.3324 | E46: Alakatot, tunnit | G46: =G44/G5 -> 138.65546
A48: Hinta, Maalaukset | B48: =B44+B46 -> 6632.8111 | C48: =C44+C46 -> 10008.882
A49: %-osuus urakasta | C49: =C44/B120 -> 0.15957409
...

Sheet Koontisivu
A3: TARJOUS
A5: Erittelyssä esitetyt hinnat alv. 0 % ilman eri mainintaa
A7: Tekniikantie 4, 2. kerros
A8: Espoo
A16: Rakennustyöt | C16: Hinta
A18: Työt | C18: =Eritelysivu!C7+Eritelysivu!C25+Eritelysivu!G25+Eritelysivu!C48+Eritelysivu!G44+Eritelysivu!C74+Eritelysivu!G74+Eritelysivu!C94 -> 60528.595
A19: Materiaalit | C19: =Eritelysivu!C14+Eritelysivu!B25+Eritelysivu!F25+Eritelysivu!B48+Eritelysivu!F44+Eritelysivu!B74+Eritelysivu!F74+Eritelysivu!B94 -> 84439.929
A21: Yhteensä | C21: =SUM(C18:C20) -> 144968.52
A23: Erillishankinnat | C23: Hinta | D23: Selite
A24: =Eritelysivu!C99 -> 0 | C24: =Eritelysivu!B99 -> 11454.545 | D24: =Eritelysivu!E99 -> Lasielementit
A25: =Eritelysivu!C100 -> 0 | C25: =Eritelysivu!B100 -> 11363.636 | D25: =Eritelysivu!E100 -> Yleissiivoukset ja loppusiivous
A26: =Eritelysivu!C101 -> 0 | C26: =Eritelysivu!B101 -> 6363.6364 | D26: =Eritelysivu!E101 -> 2 kpl aluprofiiliovet hissiaulaan
A27: =Eritelysivu!C102 -> 0 | C27: =Eritelysivu!B102 -> 0 | D27: =Eritelysivu!E102 -> 0
A28: =Eritelysivu!C103 -> 0 | C28: =Eritelysivu!B103 -> 0 | D28: =Eritelysivu!E103 -> 0
A29: =Eritelysivu!C104 -> 0 | C29: =Eritelysivu!B104 -> 0 | D29: =Eritelysivu!E104 -> 0
A30: =Eritelysivu!C105 -> 0 | C30: =Eritelysivu!B105 -> 0 | D30: =Eritelysivu!E105 -> 0
A31: =Eritelysivu!C106 -> 0 | C31: =Eritelysivu!B106 -> 0 | D31: =Eritelysivu!E106 -> 0
A32: =Eritelysivu!C107 -> 0 | C32: =Eritelysivu!B107 -> 0 | D32: =Eritelysivu!E107 -> 0
A33: =Eritelysivu!C108 -> 0 | C33: =Eritelysivu!B108 -> 0 | D33: =Eritelysivu!E108 -> 0
A34: =Eritelysivu!C109 -> 0 | C34: =Eritelysivu!B109 -> 0 | D34: =Eritelysivu!E109 -> 0
A35: =Eritelysivu!C110 -> 0 | C35: =Eritelysivu!B110 -> 0 | D35: =Eritelysivu!E110 -> 0
... A38: =Eritelysivu!C113 -> 0 | C38: =Eritelysivu!B113 -> 0 | D38: =Eritelysivu!E113 -> 0
A39: Erillishankinnat yhteensä | C39: =SUM(C24:C38) -> 29181.818
A41: Tarjous yhteensä | C41: =C21+C39 -> 174150.34

Sheet Massalista, rak. tarvikkeet 
C1: Massalistat | F1: <- Valitse tyhjät tilauslistaa varten
G2: Tarkasta positioiden rangat ja muut tavikkeet laskentasivuilta!
A3: Väliseinät | C3: Väliseinätarvikkeet | D3: Yhteensä | E3: Yhteensä | G3: POS-1 | H3: POS-2 | I3: POS-3 | J3: POS-4 | K3: POS-5 | L3: POS-6 | M3: POS-7 | N3: POS-8
C4: Levy, m2 | D4: =SUM(G4:N4) -> 1553.2 | E4: =ROUNDUP(D4,0) -> 1554 | G4: ='Väliseinät sisällä'!H7 -> 1553.2 | H4: ='Väliseinät sisällä'!H52 -> 0 | I4: ='Väliseinät sisällä'!H96 -> 0 | J4: ='Väliseinät sisällä'!H139 -> 0 | K4: ='Väliseinät sisällä'!H182 -> 0 | L4: ='Väliseinät sisällä'!H225 -> 0 | M4: ='Väliseinät sisällä'!H268 -> 0 | N4: ='Väliseinät sisällä'!H311 -> 0
C5: Ranka, m | D5: =SUM(G5:N5) -> 680.3027 | E5: =ROUNDUP(D5,0) -> 681 | G5: ='Väliseinät sisällä'!H8 -> 680.3027 | H5: ='Väliseinät sisällä'!H53 -> 0 | I5: ='Väliseinät sisällä'!H97 -> 0 | J5: ='Väliseinät sisällä'!H140 -> 0 | K5: ='Väliseinät sisällä'!H183 -> 0 | L5: ='Väliseinät sisällä'!H226 -> 0 | M5: ='Väliseinät sisällä'!H269 -> 0 | N5: ='Väliseinät sisällä'!H312 -> 0
C6: Alakisko, seinä, m / otsat max 600, m | D6: =SUM(G6:N6) -> 311.7895 | E6: =ROUNDUP(D6,0) -> 312 | G6: ='Väliseinät sisällä'!H9 -> 311.7895 | H6: ='Väliseinät sisällä'!H54 -> 0 | I6: ='Väliseinät sisällä'!H98 -> 0 | J6: ='Väliseinät sisällä'!H141 -> 0 | K6: ='Väliseinät sisällä'!H184 -> 0 | L6: ='Väliseinät sisällä'!H227 -> 0 | M6: ='Väliseinät sisällä'!H270 -> 0 | N6: ='Väliseinät sisällä'!H313 -> 0
C7: Villa, m2 | D7: =SUM(G7:N7) -> 368.5 | E7: =ROUNDUP(D7,0) -> 369 | G7: ='Väliseinät sisällä'!H10 -> 368.5 | H7: ='Väliseinät sisällä'!H55 -> 0 | I7: ='Väliseinät sisällä'!H99 -> 0 | J7: ='Väliseinät sisällä'!H142 -> 0 | K7: ='Väliseinät sisällä'!H185 -> 0 | L7: ='Väliseinät sisällä'!H228 -> 0 | M7: ='Väliseinät sisällä'!H271 -> 0 | N7: ='Väliseinät sisällä'!H314 -> 0
C8: Ruuvit, kpl / 1000 kpl pkt | D8: =SUM(G8:N8)/1000 -> 24.486 | E8: =ROUNDUP(D8,0) -> 25 | G8: ='Väliseinät sisällä'!H11 -> 24486 | H8: ='Väliseinät sisällä'!H56 -> 0 | I8: ='Väliseinät sisällä'!H100 -> 0 | J8: ='Väliseinät sisällä'!H143 -> 0 | K8: ='Väliseinät sisällä'!H186 -> 0 | L8: ='Väliseinät sisällä'!H229 -> 0 | M8: ='Väliseinät sisällä'!H272 -> 0 | N8: ='Väliseinät sisällä'!H315 -> 0
C9: Runkokiinnike, kpl | D9: =SUM(G9:N9) -> 137.18738 | E9: =ROUNDUP(D9,0) -> 138 | G9: ='Väliseinät sisällä'!H12 -> 137.18738 | H9: ='Väliseinät sisällä'!H57 -> 0 | I9: ='Väliseinät sisällä'!H101 -> 0 | J9: ='Väliseinät sisällä'!H144 -> 0 | K9: ='Väliseinät sisällä'!H187 -> 0 | L9: ='Väliseinät sisällä'!H230 -> 0 | M9: ='Väliseinät sisällä'!H273 -> 0 | N9: ='Väliseinät sisällä'!H316 -> 0
C10: Vahvike, esim kertopuu, metrit | D10: =SUM(G10:N10) -> 110 | E10: =ROUNDUP(D10,0) -> 110 | G10: ='Väliseinät sisällä'!H13 -> 110 | H10: ='Väliseinät sisällä'!H58 -> 0 | I10: ='Väliseinät sisällä'!H102 -> 0 | J10: ='Väliseinät sisällä'!H145 -> 0 | K10: ='Väliseinät sisällä'!H188 -> 0 | L10: ='Väliseinät sisällä'!H231 -> 0 | M10: ='Väliseinät sisällä'!H274 -> 0 | N10: ='Väliseinät sisällä'!H317 -> 0
C11: Ovivahvike ruuvit, kpl | D11: =SUM(G11:N11) -> 0 | E11: =ROUNDUP(D11,0) -> 0 | G11: ='Väliseinät sisällä'!H14 -> 0 | H11: ='Väliseinät sisällä'!H59 -> 0 | I11: ='Väliseinät sisällä'!H103 -> 0 | J11: ='Väliseinät sisällä'!H146 -> 0 | K11: ='Väliseinät sisällä'!H189 -> 0 | L11: ='Väliseinät sisällä'!H232 -> 0 | M11: ='Väliseinät sisällä'!H275 -> 0 | N11: ='Väliseinät sisällä'!H318 -> 0
C12: Kertopuurunko, kiinnikkeet esim hobau 90mm, kpl | D12: =SUM(G12:N12) -> 1039.2983 | E12: =ROUNDUP(D12,0) -> 1040 | G12: ='Väliseinät sisällä'!H15 -> 1039.2983 | H12: ='Väliseinät sisällä'!H60 -> 0 | I12: ='Väliseinät sisällä'!H104 -> 0 | J12: ='Väliseinät sisällä'!H147 -> 0 | K12: ='Väliseinät sisällä'!H190 -> 0 | L12: ='Väliseinät sisällä'!H233 -> 0 | M12: ='Väliseinät sisällä'!H276 -> 0 | N12: ='Väliseinät sisällä'!H319 -> 0
C14: Runkokiinnike, Spit Pulsa naulat | D14: ='Väliseinät sisällä'!B32 -> 4 | E14: =ROUNDUP(D14,0) -> 4
C15: Hobarit, 90mm | D15: ='Väliseinät sisällä'!B33 -> 5 | E15: =ROUNDUP(D15,0) -> 5
C16: Pientarvikkeet, tarkasta laskentasivulta tavarat | D16: ='Väliseinät sisällä'!B34 -> 500 | E16: =ROUNDUP(D16,0) -> 500
C18: SAUMAUS
C19: J, 10 kg purkki | D19: =SUM(G19:N19)/10 -> 5.025 | E19: =ROUNDUP(D19,0) -> 6 | G19: ='Väliseinät sisällä'!H18 -> 50.25 | H19: ='Väliseinät sisällä'!H63 -> 0 | I19: ='Väliseinät sisällä'!H107 -> 0 | J19: ='Väliseinät sisällä'!H150 -> 0 | K19: ='Väliseinät sisällä'!H193 -> 0 | L19: ='Väliseinät sisällä'!H236 -> 0 | M19: ='Väliseinät sisällä'!H279 -> 0 | N19: ='Väliseinät sisällä'!H322 -> 0
C20: LF, 10 kg purkki | D20: =SUM(G20:N20)/10 -> 5.025 | E20: =ROUNDUP(D20,0) -> 6 | G20: ='Väliseinät sisällä'!H19 -> 50.25 | H20: ='Väliseinät sisällä'!H64 -> 0 | I20: ='Väliseinät sisällä'!H108 -> 0 | J20: ='Väliseinät sisällä'!H151 -> 0 | K20: ='Väliseinät sisällä'!H194 -> 0 | L20: ='Väliseinät sisällä'!H237 -> 0 | M20: ='Väliseinät sisällä'!H280 -> 0 | N20: ='Väliseinät sisällä'!H323 -> 0
C21: Akryyli, makkara | D21: =SUM(G21:N21) -> 166.66667 | E21: =ROUNDUP(D21,0) -> 167 | G21: ='Väliseinät sisällä'!H20 -> 166.66667 | H21: ='Väliseinät sisällä'!H65 -> 0 | I21: ='Väliseinät sisällä'!H109 -> 0 | J21: ='Väliseinät sisällä'!H152 -> 0 | K21: ='Väliseinät sisällä'!H195 -> 0 | L21: ='Väliseinät sisällä'!H238 -> 0 | M21: ='Väliseinät sisällä'!H281 -> 0 | N21: ='Väliseinät sisällä'!H324 -> 0
C23: YLITASOITUS, 2mm kerros
C24: L, 20 kg säkit | D24: =SUM(G24:N24)/20 -> 80.4 | E24: =ROUNDUP(D24,0) -> 81 | G24: ='Väliseinät sisällä'!H22 -> 1608 | H24: ='Väliseinät sisällä'!H67 -> 0 | I24: ='Väliseinät sisällä'!H111 -> 0 | J24: ='Väliseinät sisällä'!H154 -> 0 | K24: ='Väliseinät sisällä'!H197 -> 0 | L24: ='Väliseinät sisällä'!H240 -> 0 | M24: ='Väliseinät sisällä'!H283 -> 0 | N24: ='Väliseinät sisällä'!H326 -> 0
C25: LR+, 20 kg säkit | D25: =SUM(G25:N25)/20 -> 80.4 | E25: =ROUNDUP(D25,0) -> 81 | G25: ='Väliseinät sisällä'!H23 -> 1608 | H25: ='Väliseinät sisällä'!H70 -> 0 | I25: ='Väliseinät sisällä'!H114 -> 0 | J25: ='Väliseinät sisällä'!H157 -> 0 | K25: ='Väliseinät sisällä'!H200 -> 0 | L25: ='Väliseinät sisällä'!H243 -> 0 | M25: ='Väliseinät sisällä'!H286 -> 0 | N25: ='Väliseinät sisällä'!H329 -> 0
C26: LF tai vastaava viimeistely, l / 10l purkki | D26: =SUM(G26:N26)/10 -> 40.2 | E26: =ROUNDUP(D26,0) -> 41 | G26: ='Väliseinät sisällä'!H24 -> 402 | H26: ='Väliseinät sisällä'!H71 -> 0 | I26: ='Väliseinät sisällä'!H115 -> 0 | J26: ='Väliseinät sisällä'!H158 -> 0 | K26: ='Väliseinät sisällä'!H201 -> 0 | L26: ='Väliseinät sisällä'!H244 -> 0 | M26: ='Väliseinät sisällä'!H287 -> 0 | N26: ='Väliseinät sisällä'!H330 -> 0
A29: Maalaukset | C29: Maalaustyöt | E29: Yhteensä | G29: POS-1 | H29: POS-2 | I29: POS-3 | J29: POS-4 | K29: POS-5 | L29: POS-6 | M29: POS-7 | N29: POS-8 | O29: POS-9 | P29: POS-10
C30: Teippi, rll | E30: =SUM(G30:P30) -> 33 | G30: =Maalaukset!K6 -> 33 | H30: =Maalaukset!K39 -> 0 | I30: =Maalaukset!K72 -> 0 | J30: =Maalaukset!K105 -> 0 | K30: =Maalaukset!K138 -> 0 | L30: =Maalaukset!K171 -> 0 | M30: =Maalaukset!K204 -> 0 | N30: =Maalaukset!K237 -> 0 | O30: =Maalaukset!K270 -> 0 | P30: =Maalaukset!K303 -> 0
C31: Vetonit L | E31: =SUM(G31:P31) -> 0 | G31: =Maalaukset!K11 -> 0 | H31: =Maalaukset!K44 -> 0 | I31: =Maalaukset!K77 -> 0 | J31: =Maalaukset!K110 -> 0 | K31: =Maalaukset!K143 -> 0 | L31: =Maalaukset!K176 -> 0 | M31: =Maalaukset!K209 -> 0 | N31: =Maalaukset!K242 -> 0 | O31: =Maalaukset!K275 -> 0 | P31: =Maalaukset!K308 -> 0
C32: Veotnit LR+ | E32: =SUM(G32:P32) -> 0 | G32: =Maalaukset!K12 -> 0 | H32: =Maalaukset!K45 -> 0 | I32: =Maalaukset!K78 -> 0 | J32: =Maalaukset!K111 -> 0 | K32: =Maalaukset!K144 -> 0 | L32: =Maalaukset!K177 -> 0 | M32: =Maalaukset!K210 -> 0 | N32: =Maalaukset!K243 -> 0 | O32: =Maalaukset!K276 -> 0 | P32: =Maalaukset!K309 -> 0
C33: Teknos LF | E33: =SUM(G33:P33) -> 0 | G33: =Maalaukset!K14 -> 0 | H33: =Maalaukset!K47 -> 0 | I33: =Maalaukset!K80 -> 0 | J33: =Maalaukset!K113 -> 0 | K33: =Maalaukset!K146 -> 0 | L33: =Maalaukset!K179 -> 0 | M33: =Maalaukset!K212 -> 0 | N33: =Maalaukset!K245 -> 0 | O33: =Maalaukset!K278 -> 0 | P33: =Maalaukset!K311 -> 0
C34: Goldband | E34: =SUM(G34:P34) -> 0 | G34: =Maalaukset!K16 -> 0 | H34: =Maalaukset!K49 -> 0 | I34: =Maalaukset!K82 -> 0 | J34: =Maalaukset!K115 -> 0 | K34: =Maalaukset!K148 -> 0 | L34: =Maalaukset!K181 -> 0 | M34: =Maalaukset!K214 -> 0 | N34: =Maalaukset!K247 -> 0 | O34: =Maalaukset!K280 -> 0 | P34: =Maalaukset!K313 -> 0
C35: Siro 2 | E35: =SUM(G35:P35) -> 32 | G35: =Maalaukset!K18 -> 31 | H35: =Maalaukset!K51 -> 1 | I35: =Maalaukset!K84 -> 0 | J35: =Maalaukset!K117 -> 0 | K35: =Maalaukset!K150 -> 0 | L35: =Maalaukset!K183 -> 0 | M35: =Maalaukset!K216 -> 0 | N35: =Maalaukset!K249 -> 0 | O35: =Maalaukset!K282 -> 0 | P35: =Maalaukset!K315 -> 0
C36: Siro 7 mv, 18l | E36: =SUM(G36:P36) -> 17 | G36: =Maalaukset!K20 -> 17 | H36: =Maalaukset!K53 -> 0 | I36: =Maalaukset!K86 -> 0 | J36: =Maalaukset!K119 -> 0 | K36: =Maalaukset!K152 -> 0 | L36: =Maalaukset!K185 -> 0 | M36: =Maalaukset!K218 -> 0 | N36: =Maalaukset!K251 -> 0 | O36: =Maalaukset!K284 -> 0 | P36: =Maalaukset!K317 -> 0
C37: Nova C + sävy | E37: =SUM(G37:P37) -> 6 | G37: =Maalaukset!K21 -> 5 | H37: =Maalaukset!K54 -> 1 | I37: =Maalaukset!K87 -> 0 | J37: =Maalaukset!K120 -> 0 | K37: =Maalaukset!K153 -> 0 | L37: =Maalaukset!K186 -> 0 | M37: =Maalaukset!K219 -> 0 | N37: =Maalaukset!K252 -> 0 | O37: =Maalaukset!K285 -> 0 | P37: =Maalaukset!K318 -> 0
C38: Maali 1 | E38: =SUM(G38:P38) -> 0 | G38: =Maalaukset!K23 -> 0 | H38: =Maalaukset!K56 -> 0 | I38: =Maalaukset!K89 -> 0 | J38: =Maalaukset!K122 -> 0 | K38: =Maalaukset!K155 -> 0 | L38: =Maalaukset!K188 -> 0 | M38: =Maalaukset!K221 -> 0 | N38: =Maalaukset!K254 -> 0 | O38: =Maalaukset!K287 -> 0 | P38: =Maalaukset!K320 -> 0
C39: Maali 2 | E39: =SUM(G39:P39) -> 0 | G39: =Maalaukset!K24 -> 0 | H39: =Maalaukset!K57 -> 0 | I39: =Maalaukset!K90 -> 0 | J39: =Maalaukset!K123 -> 0 | K39: =Maalaukset!K156 -> 0 | L39: =Maalaukset!K189 -> 0 | M39: =Maalaukset!K222 -> 0 | N39: =Maalaukset!K255 -> 0 | O39: =Maalaukset!K288 -> 0 | P39: =Maalaukset!K321 -> 0
C40: Maali 3 | E40: =SUM(G40:P40) -> 0 | G40: =Maalaukset!K25 -> 0 | H40: =Maalaukset!K58 -> 0 | I40: =Maalaukset!K91 -> 0 | J40: =Maalaukset!K124 -> 0 | K40: =Maalaukset!K157 -> 0 | L40: =Maalaukset!K190 -> 0 | M40: =Maalaukset!K223 -> 0 | N40: =Maalaukset!K256 -> 0 | O40: =Maalaukset!K289 -> 0 | P40: =Maalaukset!K322 -> 0
A42: Erillliset | C42: Erilliset tarvikkeet | E42: Kpl / m2 / jm jne.
C43: =Materiaalihinnoittelut!B4 -> GN | E43: =Materiaalihinnoittelut!E4 -> 35
C44: =Materiaalihinnoittelut!B5 -> GEK | E44: =Materiaalihinnoittelut!E5 -> 0
C45: =Materiaalihinnoittelut!B6 -> Saneerauskipsi 6MM | E45: =Materiaalihinnoittelut!E6 -> 0
C46: =Materiaalihinnoittelut!B7 -> 66 ranka | E46: =Materiaalihinnoittelut!E7 -> 0
...

Sheet Budjetti
B1: Projekti: | C1: Aika:
B2: 0384 Porkkalankatu 20 Norion
C4: Ei muutoksia | D4: Ei muutoksia | E4: Ei muutoksia
C5: X | D5: X | E5: x | F5: Täytä: | K5: Kate € | L5: Kate-%
C6: Tarjottu | D6: Laskettu | E6: Arvio | F6: Toteuma | I6: =C6 -> Tarjottu | J6: =C7+C11+C14 -> 0 | K6: =C30 -> 0
A7: 1 | B7: Purkutyöt | C7: =SUM(C8:C10) -> 0 | D7: =SUM(D8:D10) -> 0 | E7: =SUM(E8:E10) -> 7388.9706 | F7: =SUM(F8:F10) -> 1 | I7: =D6 -> Laskettu | J7: =D7+D11+D14 -> 29181.818 | K7: =J6-J7 -> -29181.818 | L7: =K7/J6 -> #DIV/0!
B8: Tuntityöt | C8: 0 | E8: =Eritelysivu!C25 -> 1976.4706 | F8: 1 | I8: =E6 -> Arvio | J8: =E7+E11+E14 -> 170648.52 | K8: =J6-J8 -> -170648.52 | L8: =K8/J6 -> #DIV/0!
B9: Materiaalit | C9: 0 | E9: =Eritelysivu!B25 -> 5412.5 | I9: =F6 -> Toteuma | J9: =F7+F11+F14 -> 3 | K9: =J6-J9 -> -3 | L9: =K9/J6 -> #DIV/0!
B10: Purkutyöt | C10: 0
A11: 2 | B11: Rakennusurakka | C11: =C12+C13 -> 0 | D11: =D12+D13 -> 0 | E11: =E12+E13 -> 137579.55 | F11: =F12+F13 -> 1
B12: Tuntityöt | C12: 0 | D12: 0 | E12: =Koontisivu!C18-E8 -> 58552.125 | F12: 1
B13: Materiaalit | C13: 0 | D13: 0 | E13: =Koontisivu!C19-E9 -> 79027.429
A14: 3 | B14: Erillishankinnat | C14: =SUM(C15:C29) -> 0 | D14: =SUM(D15:D29) -> 29181.818 | E14: =SUM(E15:E29) -> 25680 | F14: =SUM(F15:F29) -> 1
A15: 1 | B15: Siivous | C15: 0 | D15: =Erillishankinnat!C7 -> 11454.545 | E15: =Erillishankinnat!C4 -> 10080 | F15: 1
A16: 2 | B16: Sähköurakka | C16: 0 | D16: =Erillishankinnat!C12 -> 11363.636 | E16: =Erillishankinnat!C9 -> 10000 | F16: 0
A17: 3 | B17: LVI-urakka | C17: 0 | D17: =Erillishankinnat!C17 -> 6363.6364 | E17: =Erillishankinnat!C14 -> 5600
A18: 4 | B18: Keittiö | C18: 0 | D18: =Erillishankinnat!C22 -> 0 | E18: =Erillishankinnat!C19 -> 0
A19: 5 | B19: WC-tarvikkeet | C19: 0 | D19: =Erillishankinnat!C27 -> 0 | E19: =Erillishankinnat!C24 -> 0
A20: 6 | B20: Lasiseinät | C20: 0 | D20: =Erillishankinnat!C32 -> 0 | E20: =Erillishankinnat!C29 -> 0
A21: 7 | B21: Lukitus | C21: 0 | D21: =Erillishankinnat!C37 -> 0 | E21: =Erillishankinnat!C34 -> 0
A22: 8 | B22: MUUT | C22: 0 | D22: =Erillishankinnat!C42 -> 0 | E22: =Erillishankinnat!C39 -> 0
A23: 9 | C23: 0 | D23: =Erillishankinnat!C47 -> 0 | E23: =Erillishankinnat!C44 -> 0
A24: 10 | C24: 0 | D24: =Erillishankinnat!C52 -> 0 | E24: =Erillishankinnat!C49 -> 0
A25: 11 | C25: 0 | D25: =Erillishankinnat!C57 -> 0 | E25: =Erillishankinnat!C54 -> 0
A26: 12 | C26: 0 | D26: =Erillishankinnat!C62 -> 0 | E26: =Erillishankinnat!C59 -> 0
A27: 13 | C27: 0 | D27: =Erillishankinnat!C67 -> 0 | E27: =Erillishankinnat!C64 -> 0
A28: 14 | C28: 0 | D28: =Erillishankinnat!C72 -> 0 | E28: =Erillishankinnat!C69 -> 0
A29: 15 | C29: 0 | D29: =Erillishankinnat!C77 -> 0 | E29: =Erillishankinnat!C74 -> 0
C30: =C14+C11+C7 -> 0 | D30: =D14+D11+D7 -> 29181.818 | E30: =E14+E11+E7 -> 170648.52 | F30: =F14+F11+F7 -> 3
C31: Tarjottu | D31: Laskettu | E31: Arvio | F31: Toteuma
